Workbook

Sheet Planilha1
B5: EQUIPAMENTOS | J5: ATRIBUTOS | V5: EQUIPAMENTO | AA5: LOCALIZAÇÃO
B7: Coluna1 | C7: Coluna2 | D7: TIPO | E7: SIGLA | F7: BLOCO | G7: Coluna4 | H7: Coluna5 | J7: Coluna1 | K7: Coluna2 | L7: TIPO | M7: Coluna4 | N7: FUNÇÃO | O7: SIGLA | P7: Descrição | V7: SIGLA | X7: SEQUENCIAL | AA7: ÁREA | AC7: LINHA | AE7: GRUPO
B8: A | C8: L | D8: ALIMENTADOR | E8: =_xlfn.CONCAT(Tabela2[[#This Row],[Coluna1]],Tabela2[[#This Row],[Coluna2]]) -> AL | J8: S | K8: N | L8: SENSOR DE NIVEL | M8: A | N8: ALTO | O8: =CONCATENATE(J8,K8,M8) -> SNA | P8: =CONCATENATE(L8," ",N8) -> SENSOR DE NIVEL ALTO | V8: EL | X8: 0 | Y8: 1 | Z8: - | AA8: R | AC8: 1 | AE8: 0 | AF8: 1
B9: B | C9: L | D9: BALANÇA | E9: =_xlfn.CONCAT(Tabela2[[#This Row],[Coluna1]],Tabela2[[#This Row],[Coluna2]]) -> BL | J9: S | K9: N | L9: SENSOR DE NIVEL | M9: M | N9: MÉDIO | O9: =CONCATENATE(J9,K9,M9) -> SNM | P9: =CONCATENATE(L9," ",N9) -> SENSOR DE NIVEL MÉDIO
B10: B | C10: B | D10: BOMBA | E10: =_xlfn.CONCAT(Tabela2[[#This Row],[Coluna1]],Tabela2[[#This Row],[Coluna2]]) -> BB | J10: S | K10: N | L10: SENSOR DE NIVEL | M10: B | N10: BAIXO | O10: =CONCATENATE(J10,K10,M10) -> SNB | P10: =CONCATENATE(L10," ",N10) -> SENSOR DE NIVEL BAIXO | AA10: R = RECEBIMENTO
B11: B | C11: T | D11: BOTOEIRA | E11: =_xlfn.CONCAT(Tabela2[[#This Row],[Coluna1]],Tabela2[[#This Row],[Coluna2]]) -> BT | J11: S | K11: P | L11: SENSOR DE POSIÇÃO | M11: A | N11: ABERTO | O11: =CONCATENATE(J11,K11,M11) -> SPA | P11: =CONCATENATE(L11," ",N11) -> SENSOR DE POSIÇÃO ABERTO | AA11: A= PLANTA A
B12: C | C12: V | D12: CALHA VIBRATÓRIA | E12: =_xlfn.CONCAT(Tabela2[[#This Row],[Coluna1]],Tabela2[[#This Row],[Coluna2]]) -> CV | J12: S | K12: P | L12: SENSOR DE POSIÇÃO | M12: F | N12: FECHADO | O12: =CONCATENATE(J12,K12,M12) -> SPF | P12: =CONCATENATE(L12," ",N12) -> SENSOR DE POSIÇÃO FECHADO | AA12: B= PLANTA B
B13: C | C13: D | D13: CONDICIONADOR | E13: =_xlfn.CONCAT(Tabela2[[#This Row],[Coluna1]],Tabela2[[#This Row],[Coluna2]]) -> CD | J13: S | K13: P | L13: SENSOR DE POSIÇÃO | M13: S | N13: SUPERIOR | O13: =CONCATENATE(J13,K13,M13) -> SPS | P13: =CONCATENATE(L13," ",N13) -> SENSOR DE POSIÇÃO SUPERIOR | AA13: C= PLANTA C
B14: E | C14: L | D14: ELEVADOR | E14: =_xlfn.CONCAT(Tabela2[[#This Row],[Coluna1]],Tabela2[[#This Row],[Coluna2]]) -> EL | J14: S | K14: P | L14: SENSOR DE POSIÇÃO | M14: I | N14: INFERIROR | O14: =CONCATENATE(J14,K14,M14) -> SPI | P14: =CONCATENATE(L14," ",N14) -> SENSOR DE POSIÇÃO INFERIROR | AA14: D= PLANTA D
B15: E | C15: S | D15: ENSACADEIRA | E15: =_xlfn.CONCAT(Tabela2[[#This Row],[Coluna1]],Tabela2[[#This Row],[Coluna2]]) -> ES | J15: S | K15: P | L15: SENSOR DE POSIÇÃO | M15: D | N15: DIANTEIRO | O15: =CONCATENATE(J15,K15,M15) -> SPD | P15: =CONCATENATE(L15," ",N15) -> SENSOR DE POSIÇÃO DIANTEIRO
B16: E | C16: X | D16: EXAUSTOR | E16: =_xlfn.CONCAT(Tabela2[[#This Row],[Coluna1]],Tabela2[[#This Row],[Coluna2]]) -> EX | J16: S | K16: P | L16: SENSOR DE POSIÇÃO | M16: T | N16: TRASEIRO | O16: =CONCATENATE(J16,K16,M16) -> SPT | P16: =CONCATENATE(L16," ",N16) -> SENSOR DE POSIÇÃO TRASEIRO
B17: E | C17: T | D17: EXTRUSORA | E17: =_xlfn.CONCAT(Tabela2[[#This Row],[Coluna1]],Tabela2[[#This Row],[Coluna2]]) -> ET | J17: E | K17: V | L17: ELETRO VÁLVULA | M17: A | N17: ABRE | O17: =CONCATENATE(J17,K17,M17) -> EVA | P17: =CONCATENATE(L17," ",N17) -> ELETRO VÁLVULA ABRE
B18: F | C18: T | D18: FILTRO | E18: =_xlfn.CONCAT(Tabela2[[#This Row],[Coluna1]],Tabela2[[#This Row],[Coluna2]]) -> FT | J18: E | K18: V | L18: ELETRO VÁLVULA | M18: F | N18: FECHA | O18: =CONCATENATE(J18,K18,M18) -> EVF | P18: =CONCATENATE(L18," ",N18) -> ELETRO VÁLVULA FECHA
B19: M | C19: T | D19: MISTURADOR | E19: =_xlfn.CONCAT(Tabela2[[#This Row],[Coluna1]],Tabela2[[#This Row],[Coluna2]]) -> MT | J19: T | K19: S | L19: TRAVA SEGURANÇA | M19: F | N19: FECHADA | O19: =CONCATENATE(J19,K19,M19) -> TSF | P19: =CONCATENATE(L19," ",N19) -> TRAVA SEGURANÇA FECHADA
B20: M | C20: G | D20: MOEGA | E20: =_xlfn.CONCAT(Tabela2[[#This Row],[Coluna1]],Tabela2[[#This Row],[Coluna2]]) -> MG | J20: T | K20: V | L20: TRAVA | M20: F | N20: FECHADA | O20: =CONCATENATE(J20,K20,M20) -> TVF | P20: =CONCATENATE(L20," ",N20) -> TRAVA FECHADA
B21: M | C21: O | D21: MOINHO | E21: =_xlfn.CONCAT(Tabela2[[#This Row],[Coluna1]],Tabela2[[#This Row],[Coluna2]]) -> MO | J21: B | K21: T | L21: BOTÃO | M21: E | N21: EMERGENCIA | O21: =CONCATENATE(J21,K21,M21) -> BTE | P21: =CONCATENATE(L21," ",N21) -> BOTÃO EMERGENCIA
B22: P | C22: N | D22: PENEIRA | E22: =_xlfn.CONCAT(Tabela2[[#This Row],[Coluna1]],Tabela2[[#This Row],[Coluna2]]) -> PN | J22: B | K22: T | L22: BOTÃO | M22: R | N22: RESET | O22: =CONCATENATE(J22,K22,M22) -> BTR | P22: =CONCATENATE(L22," ",N22) -> BOTÃO RESET
B23: P | C23: S | D23: PRENSA | E23: =_xlfn.CONCAT(Tabela2[[#This Row],[Coluna1]],Tabela2[[#This Row],[Coluna2]]) -> PS | J23: B | K23: T | L23: BOTÃO | M23: L | N23: LIGA | O23: =CONCATENATE(J23,K23,M23) -> BTL | P23: =CONCATENATE(L23," ",N23) -> BOTÃO LIGA | V23: EL01-R101
B24: Q | C24: G | D24: QUEBRADOR DE GRUMOS | E24: =_xlfn.CONCAT(Tabela2[[#This Row],[Coluna1]],Tabela2[[#This Row],[Coluna2]]) -> QG | J24: B | K24: T | L24: BOTÃO | M24: D | N24: DESLIGA | O24: =CONCATENATE(J24,K24,M24) -> BTD | P24: =CONCATENATE(L24," ",N24) -> BOTÃO DESLIGA | V24: TC01-R101
B25: Q | C25: M | D25: QUEIMADOR | E25: =_xlfn.CONCAT(Tabela2[[#This Row],[Coluna1]],Tabela2[[#This Row],[Coluna2]]) -> QM | J25: B | K25: T | L25: BOTÃO | M25: A | N25: ABRE | O25: =CONCATENATE(J25,K25,M25) -> BTA | P25: =CONCATENATE(L25," ",N25) -> BOTÃO ABRE | V25: GP01-R101 | Z25: SPA1-GP01-R101
B26: R | C26: C | D26: RECOBRIDOR | E26: =_xlfn.CONCAT(Tabela2[[#This Row],[Coluna1]],Tabela2[[#This Row],[Coluna2]]) -> RC | J26: B | K26: T | L26: BOTÃO | M26: F | N26: FECHA | O26: =CONCATENATE(J26,K26,M26) -> BTF | P26: =CONCATENATE(L26," ",N26) -> BOTÃO FECHA | Z26: SPF1-GP01-R101
B27: R | C27: F | D27: RESFRIADOR | E27: =_xlfn.CONCAT(Tabela2[[#This Row],[Coluna1]],Tabela2[[#This Row],[Coluna2]]) -> RF | J27: B | K27: T | L27: BOTÃO | M27: M | N27: MANUAL | O27: =CONCATENATE(J27,K27,M27) -> BTM | P27: =CONCATENATE(L27," ",N27) -> BOTÃO MANUAL | Z27: EVA1-GP01-R101
B28: R | C28: S | D28: RESISTÊNCIA | E28: =_xlfn.CONCAT(Tabela2[[#This Row],[Coluna1]],Tabela2[[#This Row],[Coluna2]]) -> RS | J28: B | K28: T | L28: BOTÃO | M28: U | N28: AUTOMÁTICO | O28: =CONCATENATE(J28,K28,M28) -> BTU | P28: =CONCATENATE(L28," ",N28) -> BOTÃO AUTOMÁTICO | Z28: EVF1-GP01-R101
B29: R | C29: O | D29: ROSCA | E29: =_xlfn.CONCAT(Tabela2[[#This Row],[Coluna1]],Tabela2[[#This Row],[Coluna2]]) -> RO | J29: M | K29: T | L29: MOTOR | M29: E | N29: ELÉTRICO | O29: =CONCATENATE(J29,K29,M29) -> MTE | P29: =CONCATENATE(L29," ",N29) -> MOTOR ELÉTRICO | V29: GP02-R101 | Z29: SPA1-GP02-R101
B30: S | C30: C | D30: SECADOR | E30: =_xlfn.CONCAT(Tabela2[[#This Row],[Coluna1]],Tabela2[[#This Row],[Coluna2]]) -> SC | J30: A | K30: L | L30: ALIMENTAÇÃO | M30: P | N30: POTÊNCIA | O30: =CONCATENATE(J30,K30,M30) -> ALP | P30: =CONCATENATE(L30," ",N30) -> ALIMENTAÇÃO POTÊNCIA | Z30: SPF1-GP02-R101
B31: S | C31: G | D31: SEPARADOR MAGNÉTICO | E31: =_xlfn.CONCAT(Tabela2[[#This Row],[Coluna1]],Tabela2[[#This Row],[Coluna2]]) -> SG | J31: C | K31: L | L31: CHAVE LOTO | M31: L | N31: LIGADA | O31: =CONCATENATE(J31,K31,M31) -> CLL | P31: =CONCATENATE(L31," ",N31) -> CHAVE LOTO LIGADA | Z31: EVA1-GP02-R101
B32: S | C32: L | D32: SILOS | E32: =_xlfn.CONCAT(Tabela2[[#This Row],[Coluna1]],Tabela2[[#This Row],[Coluna2]]) -> SL | J32: S | K32: S | L32: SENSOR DE SEGURANÇA | M32: F | N32: FECHADO | O32: =CONCATENATE(J32,K32,M32) -> SSF | P32: =CONCATENATE(L32," ",N32) -> SENSOR DE SEGURANÇA FECHADO | Z32: EVF1-GP02-R101
B33: S | C33: O | D33: SOPRADOR | E33: =_xlfn.CONCAT(Tabela2[[#This Row],[Coluna1]],Tabela2[[#This Row],[Coluna2]]) -> SO | J33: T | K33: S | L33: TRAVA DE SEGURANÇA | M33: D | N33: DESTRAVADA | O33: =CONCATENATE(J33,K33,M33) -> TSD | P33: =CONCATENATE(L33," ",N33) -> TRAVA DE SEGURANÇA DESTRAVADA
B34: T | C34: L | D34: TALHA | E34: =_xlfn.CONCAT(Tabela2[[#This Row],[Coluna1]],Tabela2[[#This Row],[Coluna2]]) -> TL | J34: S | K34: T | L34: SENSOR DE TEMPERATURA | M34: V | N34: VARIAVEL | O34: =CONCATENATE(J34,K34,M34) -> STV | P34: =CONCATENATE(L34," ",N34) -> SENSOR DE TEMPERATURA VARIAVEL
B35: T | C35: R | D35: TORRE RESFRIAMENTO | E35: =_xlfn.CONCAT(Tabela2[[#This Row],[Coluna1]],Tabela2[[#This Row],[Coluna2]]) -> TR | J35: S | K35: T | L35: SENSOR DE TEMPERATURA | M35: A | N35: ALTO | O35: =CONCATENATE(J35,K35,M35) -> STA | P35: =CONCATENATE(L35," ",N35) -> SENSOR DE TEMPERATURA ALTO
B36: T | C36: C | D36: TRANSPORTADOR CORRENTE | E36: =_xlfn.CONCAT(Tabela2[[#This Row],[Coluna1]],Tabela2[[#This Row],[Coluna2]]) -> TC | J36: S | K36: T | L36: SENSOR DE TEMPERATURA | M36: B | N36: BAIXO | O36: =CONCATENATE(J36,K36,M36) -> STB | P36: =CONCATENATE(L36," ",N36) -> SENSOR DE TEMPERATURA BAIXO
B37: T | C37: F | D37: TRANSPORTADOR FITA | E37: =_xlfn.CONCAT(Tabela2[[#This Row],[Coluna1]],Tabela2[[#This Row],[Coluna2]]) -> TF | J37: S | K37: M | L37: SENSOR DE MOVIMENTO | M37: A | N37: ACIONADO | O37: =CONCATENATE(J37,K37,M37) -> SMA | P37: =CONCATENATE(L37," ",N37) -> SENSOR DE MOVIMENTO ACIONADO
B38: T | C38: T | D38: TRITURADOR | E38: =_xlfn.CONCAT(Tabela2[[#This Row],[Coluna1]],Tabela2[[#This Row],[Coluna2]]) -> TT | J38: S | K38: E | L38: SENSOR EMBUCHAMENTO | M38: A | N38: ACIONADO | O38: =CONCATENATE(J38,K38,M38) -> SEA | P38: =CONCATENATE(L38," ",N38) -> SENSOR EMBUCHAMENTO ACIONADO
B39: T | C39: C | D39: TROCADOR DE CALOR | E39: =_xlfn.CONCAT(Tabela2[[#This Row],[Coluna1]],Tabela2[[#This Row],[Coluna2]]) -> TC | J39: S | K39: N | L39: SENSOR DE NIVEL | M39: V | N39: VARIAVEL | O39: =CONCATENATE(J39,K39,M39) -> SNV | P39: =CONCATENATE(L39," ",N39) -> SENSOR DE NIVEL VARIAVEL
B40: G | C40: M | D40: GAVETA MANUAL | E40: =_xlfn.CONCAT(Tabela2[[#This Row],[Coluna1]],Tabela2[[#This Row],[Coluna2]]) -> GM | J40: S | K40: D | L40: SENSOR DESALINHAMENTO | M40: V | N40: VARIAVEL | O40: =CONCATENATE(J40,K40,M40) -> SDV | P40: =CONCATENATE(L40," ",N40) -> SENSOR DESALINHAMENTO VARIAVEL
B41: G | C41: P | D41: GAVETA PNEUMÁTICA | E41: =_xlfn.CONCAT(Tabela2[[#This Row],[Coluna1]],Tabela2[[#This Row],[Coluna2]]) -> GP | J41: S | K41: D | L41: SENSOR DESALINHAMENTO | M41: A | N41: ACIONADO | O41: =CONCATENATE(J41,K41,M41) -> SDA | P41: =CONCATENATE(L41," ",N41) -> SENSOR DESALINHAMENTO ACIONADO
B42: G | C42: A | D42: GAVETA ACOPLADORA | E42: =_xlfn.CONCAT(Tabela2[[#This Row],[Coluna1]],Tabela2[[#This Row],[Coluna2]]) -> GA | J42: S | K42: F | L42: SENSOR DE FLUXO | M42: V | N42: VARIÁVEL | O42: =CONCATENATE(J42,K42,M42) -> SFV | P42: =CONCATENATE(L42," ",N42) -> SENSOR DE FLUXO VARIÁVEL
B43: G | C43: H | D43: GAVETA HIDRÁULICA | E43: =_xlfn.CONCAT(Tabela2[[#This Row],[Coluna1]],Tabela2[[#This Row],[Coluna2]]) -> GH | J43: S | K43: R | L43: SENSOR DE PRESSÃO | M43: A | N43: ALTO | O43: =CONCATENATE(J43,K43,M43) -> SRA | P43: =CONCATENATE(L43," ",N43) -> SENSOR DE PRESSÃO ALTO
B44: V | C44: I | D44: VIBRADOR | E44: =_xlfn.CONCAT(Tabela2[[#This Row],[Coluna1]],Tabela2[[#This Row],[Coluna2]]) -> VI | J44: S | K44: R | L44: SENSOR DE PRESSÃO | M44: B | N44: BAIXO | O44: =CONCATENATE(J44,K44,M44) -> SRB | P44: =CONCATENATE(L44," ",N44) -> SENSOR DE PRESSÃO BAIXO
... B46: D | C46: T | D46: DISTRIBUIDOR | E46: =_xlfn.CONCAT(Tabela2[[#This Row],[Coluna1]],Tabela2[[#This Row],[Coluna2]]) -> DT | J46: S | K46: A | L46: SENSOR DETECÇÃO DE PARTICULAS | M46: V | N46: VARIÁVEL | O46: =CONCATENATE(J46,K46,M46) -> SAV | P46: =CONCATENATE(L46," ",N46) -> SENSOR DETECÇÃO DE PARTICULAS VARIÁVEL
...

Sheet Regras
B2: REGRAS DE FORMAÇÃO DE TAGs — PADRÃO STW
B3: Esta folha documenta as máscaras de TAG, a legenda de áreas e exemplos. Células amarelas são editáveis; as demais são calculadas.
B4: Legenda: | C4: Editável | D4: Calculado
B6: 1. TAG de equipamento — máscara AA00-A000
B7: Letras (A) = alfabético · Dígitos (0) = numérico · “-” = separador fixo
B8: Posição | C8: Campo | D8: Tamanho | E8: Tipo | F8: Valores válidos | G8: Regra | H8: Exemplo
B9: 1–2 | C9: Sigla | D9: 2 | E9: Letras | F9: Tabela2 (coluna SIGLA) | G9: Tipo de equipamento, conforme Tabela2 da Planilha1 | H9: EL
B10: 3–4 | C10: Sequencial | D10: 2 | E10: Dígitos | F10: 01 a 99 | G10: Numera equipamentos do mesmo tipo no mesmo grupo, a partir de 01 | H10: 01
B11: 5 | C11: Separador | D11: 1 | E11: Fixo | F11: - | G11: Separa identificação e localização | H11: -
B12: 6 | C12: Área | D12: 1 | E12: Letra | F12: R, A, B, C, D | G12: Ver legenda de áreas (item 3) | H12: R
B13: 7 | C13: Linha | D13: 1 | E13: Dígito | F13: 1 a 9 | G13: Linha de produção dentro da área | H13: 1
B14: 8–9 | C14: Grupo | D14: 2 | E14: Dígitos | F14: 01 a 99 | G14: Conjunto de equipamentos dentro da linha | H14: 01
B16: Resultado: | C16: EL01-R101 | D16: → Elevador nº 01 · Recebimento · linha 1 · grupo 01
B19: 2. TAG de atributo (sinal) — máscara AAA0-AA00-A000
B20: O atributo sempre termina com o TAG completo do equipamento “pai”.
B21: Posição | C21: Campo | D21: Tamanho | E21: Tipo | F21: Valores válidos | G21: Regra | H21: Exemplo
B22: 1 | C22: Tipo | D22: 1 | E22: Letra | F22: Tabela1 (Coluna1) | G22: S = sensor, E = eletroválvula, B = botão, T = trava, M = motor… | H22: S
B23: 2 | C23: Variável | D23: 1 | E23: Letra | F23: Tabela1 (Coluna2) | G23: N = nível, P = posição, T = temperatura, R = pressão… | H23: P
B24: 3 | C24: Função / estado | D24: 1 | E24: Letra | F24: Tabela1 (Coluna4) | G24: A = aberto/alto, F = fechado, B = baixo, V = variável… | H24: A
B25: 4 | C25: Índice | D25: 1 | E25: Dígito | F25: 1 a 9 | G25: Diferencia sinais iguais no mesmo equipamento | H25: 1
B26: 5 | C26: Separador | D26: 1 | E26: Fixo | F26: - | G26: Separa o sinal do equipamento | H26: -
B27: 6–14 | C27: Equipamento pai | D27: 9 | E27: Máscara | F27: AA00-A000 | G27: TAG completo do equipamento (item 1) | H27: GP01-R101
B29: Resultado: | C29: SPA1-GP01-R101 | E29: → Sensor de posição “aberto” nº 1 da Gaveta pneumática 01
B32: 3. Legenda de áreas
B33: Código | C33: Área
B34: R | C34: Recebimento
B35: A | C35: Planta A
B36: B | C36: Planta B
B37: C | C37: Planta C
B38: D | C38: Planta D
B40: 4. Exemplos — equipamento (decomposição automática)
B41: Digite o TAG na coluna B; as demais colunas são calculadas.
B42: TAG | C42: Sigla | D42: Sequencial | E42: Área | F42: Linha / Grupo | G42: Equipamento | H42: Formato OK?
B43: EL01-R101 | C43: =IF(B43="","",LEFT(B43,2)) -> EL | D43: =IF(B43="","",MID(B43,3,2)) -> 01 | E43: =IF(B43="","",IFERROR(INDEX($C$34:$C$38,MATCH(MID(B43,6,1),$B$34:$B$38,0)),"área inválida")) -> Recebimento | F43: =IF(B43="","","L"&MID(B43,7,1)&" / G"&MID(B43,8,2)) -> L1 / G01 | G43: =IF(B43="","",IFERROR(INDEX(Planilha1!$D$8:$D$97,MATCH(C43,Planilha1!$E$8:$E$97,0)),"sigla não cadastrada")) -> ELEVADOR | H43: =IF(B43="","",IF(AND(LEN(B43)=9,MID(B43,5,1)="-",ISNUMBER(--MID(B43,3,2)),ISNUMBER(--MID(B43,7,3)),COUNTIF($B$34:$B$38,MID(B43,6,1))=1,COUNTIF(Planilha1!$E$8:$E$97,C43)>0),"OK","VERIFICAR")) -> OK
B44: TC01-R101 | C44: =IF(B44="","",LEFT(B44,2)) -> TC | D44: =IF(B44="","",MID(B44,3,2)) -> 01 | E44: =IF(B44="","",IFERROR(INDEX($C$34:$C$38,MATCH(MID(B44,6,1),$B$34:$B$38,0)),"área inválida")) -> Recebimento | F44: =IF(B44="","","L"&MID(B44,7,1)&" / G"&MID(B44,8,2)) -> L1 / G01 | G44: =IF(B44="","",IFERROR(INDEX(Planilha1!$D$8:$D$97,MATCH(C44,Planilha1!$E$8:$E$97,0)),"sigla não cadastrada")) -> TRANSPORTADOR CORRENTE | H44: =IF(B44="","",IF(AND(LEN(B44)=9,MID(B44,5,1)="-",ISNUMBER(--MID(B44,3,2)),ISNUMBER(--MID(B44,7,3)),COUNTIF($B$34:$B$38,MID(B44,6,1))=1,COUNTIF(Planilha1!$E$8:$E$97,C44)>0),"OK","VERIFICAR")) -> OK
B45: GP01-R101 | C45: =IF(B45="","",LEFT(B45,2)) -> GP | D45: =IF(B45="","",MID(B45,3,2)) -> 01 | E45: =IF(B45="","",IFERROR(INDEX($C$34:$C$38,MATCH(MID(B45,6,1),$B$34:$B$38,0)),"área inválida")) -> Recebimento | F45: =IF(B45="","","L"&MID(B45,7,1)&" / G"&MID(B45,8,2)) -> L1 / G01 | G45: =IF(B45="","",IFERROR(INDEX(Planilha1!$D$8:$D$97,MATCH(C45,Planilha1!$E$8:$E$97,0)),"sigla não cadastrada")) -> GAVETA PNEUMÁTICA | H45: =IF(B45="","",IF(AND(LEN(B45)=9,MID(B45,5,1)="-",ISNUMBER(--MID(B45,3,2)),ISNUMBER(--MID(B45,7,3)),COUNTIF($B$34:$B$38,MID(B45,6,1))=1,COUNTIF(Planilha1!$E$8:$E$97,C45)>0),"OK","VERIFICAR")) -> OK
B46: GP02-R101 | C46: =IF(B46="","",LEFT(B46,2)) -> GP | D46: =IF(B46="","",MID(B46,3,2)) -> 02 | E46: =IF(B46="","",IFERROR(INDEX($C$34:$C$38,MATCH(MID(B46,6,1),$B$34:$B$38,0)),"área inválida")) -> Recebimento | F46: =IF(B46="","","L"&MID(B46,7,1)&" / G"&MID(B46,8,2)) -> L1 / G01 | G46: =IF(B46="","",IFERROR(INDEX(Planilha1!$D$8:$D$97,MATCH(C46,Planilha1!$E$8:$E$97,0)),"sigla não cadastrada")) -> GAVETA PNEUMÁTICA | H46: =IF(B46="","",IF(AND(LEN(B46)=9,MID(B46,5,1)="-",ISNUMBER(--MID(B46,3,2)),ISNUMBER(--MID(B46,7,3)),COUNTIF($B$34:$B$38,MID(B46,6,1))=1,COUNTIF(Planilha1!$E$8:$E$97,C46)>0),"OK","VERIFICAR")) -> OK
B48: Obs.: TC está cadastrada duas vezes na Tabela2 (Transportador corrente e Trocador de calor); a busca retorna a primeira ocorrência.
B51: 5. Exemplos — atributo (decomposição automática)
B52: Digite o TAG na coluna B; as demais colunas são calculadas.
...
